#VRML_SIM R2021b utf8
WorldInfo {
  coordinateSystem "NUE"
  contactProperties [
    ContactProperties {
      material2 "spherical"
    }
  ]
}
Viewpoint {
  orientation 1 0 0 4.71238898038469
  position -5.720152062534232e-16 29.461914677040635 -4.316544609340311e-15
  exposure 0.6
  follow "robot"
  followType "None"
}
TexturedBackground {
  texture "mars"
  skyColor [
    0 0 0.498039
  ]
}
TexturedBackgroundLight {
  texture "mars"
}
UnevenTerrain {
  translation 0 -0.1 0
  rotation 0 0 1 0
  size 40 0 40
  perlinNOctaves 8
}
DEF WALL_1_ Solid {
  translation 0 0.1 20
  children [
    DEF WALL Shape {
      appearance PBRAppearance {
        baseColor 0.5 0.5 0.5
        roughness 1
        metalness 0
      }
      geometry Box {
        size 40 0.5 0.1
      }
    }
  ]
  boundingObject USE WALL
}
DEF WALL_2 Solid {
  translation 0 0.1 -20
  children [
    USE WALL
  ]
  name "solid(1)"
  boundingObject USE WALL
}
DEF WALL_3 Solid {
  translation 20 0.1 0
  rotation 0 1 0 1.5708
  children [
    USE WALL
  ]
  name "solid(2)"
  boundingObject USE WALL
}
DEF WALL_4 Solid {
  translation -20 0.1 0
  rotation 0 1 0 1.5708
  children [
    USE WALL
  ]
  name "solid(3)"
  boundingObject USE WALL
}
DEF SPH_ROB Robot {
  translation 0 0.16 0
  children [
    Gyro {
      name "gyroshell"
    }
    HingeJoint {
      jointParameters HingeJointParameters {
        axis 0 0 1
        suspensionAxis 0 0 1
      }
      device [
        PositionSensor {
          name "long_pos"
        }
        RotationalMotor {
          name "long_motor"
          controlPID 110 0 0
          maxVelocity 1.5
          maxTorque 0.1
        }
      ]
      endPoint Solid {
        rotation 1 0 0 1.57079632679
        children [
          Camera {
            rotation 0 1 0 -1.5708
            name "camara1"
            fieldOfView 1.3
            width 426
            height 240
            near 0.05
          }
          InertialUnit {
            name "inertial"
          }
          Gyro {
            name "gyro1"
          }
          GPS {
            name "my_gps"
          }
          HingeJoint {
            jointParameters HingeJointParameters {
            }
            device [
              PositionSensor {
                name "theta2"
              }
              RotationalMotor {
                name "steering"
                controlPID 1.7 1.74 0.01
              }
            ]
            endPoint Solid {
              translation 0 0 0.09
              rotation 1 0 0 1.5708
              children [
                InertialUnit {
                  name "inertialrod"
                }
                Solid {
                  translation 0 0.065 0
                  children [
                    DEF WEIGHT Shape {
                      appearance PBRAppearance {
                        baseColor 0.5 0.5 0.5
                        roughness 1
                        metalness 0
                      }
                      geometry Sphere {
                        radius 0.03
                        subdivision 3
                      }
                    }
                  ]
                  boundingObject USE WEIGHT
                  physics Physics {
                    density -1
                    mass 0.639
                    centerOfMass [
                      0 0.0325 0
                    ]
                    inertiaMatrix [
                      1.6760807315446848e-06 1.6760807315446848e-06 1.6760807315446848e-06
                      0 0 0
                    ]
                  }
                }
                DEF ROD Shape {
                  appearance PBRAppearance {
                    baseColor 0.5 0.5 0.5
                    roughness 1
                    metalness 0
                  }
                  geometry Cylinder {
                    height 0.18
                    radius 0.01
                  }
                }
              ]
              boundingObject USE ROD
              physics Physics {
              }
            }
          }
          DEF AXIS Shape {
            appearance PBRAppearance {
              baseColor 0.5 0.5 0.5
              roughness 1
              metalness 0
            }
            geometry Cylinder {
              height 0.4
              radius 0.01
            }
          }
        ]
        boundingObject USE AXIS
        physics Physics {
          centerOfMass [
            0 0 0
          ]
          inertiaMatrix [
            0.0024211471277448245 7.099999397112934e-06 0.0024211471277448245
            0 0 0
          ]
        }
      }
    }
    Display {
      name "display_2"
      width 500
      height 200
    }
    Display {
      name "display_1"
      recognitionColors [
        1 1 1
      ]
      width 500
      height 200
    }
    DEF CASE Shape {
      appearance PBRAppearance {
        baseColor 0 0 0
        transparency 0.6
        metalness 0
      }
      geometry Sphere {
        radius 0.2
        subdivision 3
      }
    }
  ]
  contactMaterial "spherical"
  boundingObject USE CASE
  physics Physics {
    density -1
    mass 0.5
    centerOfMass [
      0 0 0
    ]
    inertiaMatrix [
      0.0093037365783076 0.0093037365783076 0.0093037365783076
      0 0 0
    ]
  }
  translationStep 0
  rotationStep 0
  controller "torque_control_roozegar_8_linux"
}
DEF BOX2 Solid {
  translation -20 0.4 -2.5
  children [
    Shape {
      appearance Appearance {
        material Material {
          ambientIntensity 1
          diffuseColor 0.8 0 0
          shininess 0.7
        }
      }
      geometry Box {
        size 1 1 1
      }
    }
  ]
  name "solid(10)"
  boundingObject Box {
    size 1 1 1
  }
  physics Physics {
    mass 1
  }
}
DEF GOAL1 Solid {
  translation 0 -0.049 0
  children [
    DEF GOALS Shape {
      appearance PBRAppearance {
        baseColor 0 0 0
        roughness 1
        metalness 0
      }
      geometry Plane {
        size 0.1 0.1
      }
    }
  ]
  name "goal1"
}
DEF GOAL2 Solid {
  translation 0 -0.049 5
  children [
    USE GOALS
  ]
  name "solid(4)"
}
DEF GOAL3 Solid {
  translation 0 -0.049 -5
  children [
    USE GOALS
  ]
  name "solid(5)"
}
DEF GOAL4 Solid {
  translation -5 -0.049 0
  children [
    USE GOALS
  ]
  name "solid(6)"
}
DEF GOAL6 Solid {
  translation 5 -0.049 0
  children [
    USE GOALS
  ]
  name "solid(8)"
}
DEF GOAL5 Solid {
  translation 5 -0.049 -5
  children [
    USE GOALS
  ]
  name "solid(7)"
}
DEF BOX1 Solid {
  translation -20 0.4 2.5
  children [
    DEF BOXES Shape {
      appearance Appearance {
        material Material {
          ambientIntensity 1
          diffuseColor 0.8 0 0
          shininess 0.7
        }
      }
      geometry Box {
        size 1 1 1
      }
    }
  ]
  name "solid(9)"
  boundingObject Box {
    size 1 1 1
  }
  physics Physics {
    mass 1
  }
}
